Workbook
Name Staff: 'Raw data'!$A$2:$N$742

Sheet Raw data
A1: Names | B1: Building | C1: Department | D1: Status | E1: Hiring date | F1: Benefits | G1: Salary | H1: Rating
A2: Abbott, James | B2: North | C2: Quality Assurance | D2: Full Time | E2: 36526 | F2: DMR | G2: 29260 | H2: 4
A3: Acosta, Robert | B3: Main | C3: Quality Assurance | D3: Full Time | E3: 39137 | F3: DMR | G3: 39000 | H3: 5
A4: Adams, David | B4: Main | C4: Product Development | D4: Full Time | E4: 40198 | F4: D | G4: 49260 | H4: 3
A5: Adkins, Michael | B5: North | C5: Quality Assurance | D5: Full Time | E5: 40574 | F5: R | G5: 24840 | H5: 1
A6: Aguilar, Kevin | B6: West | C6: Quality Assurance | D6: Full Time | E6: 36290 | F6: R | G6: 39000 | H6: 3
A7: Alexander, Charles | B7: West | C7: Manufacturing Admin | D7: Contract | E7: 36765 | G7: 74500 | H7: 4
A8: Allen, Thomas | B8: Main | C8: Manufacturing | D8: Full Time | E8: 38807 | F8: DMR | G8: 79730 | H8: 2
A9: Allison, Timothy | B9: Main | C9: Creative | D9: Full Time | E9: 40918 | F9: M | G9: 82500 | H9: 5
A10: Alvarado, Sonia | B10: Main | C10: IT | D10: Half-Time | E10: 40807 | F10: DM | G10: 35045 | H10: 4
A11: Alvarez, Steven | B11: Taft | C11: Quality Assurance | D11: Contract | E11: 40587 | G11: 89450 | H11: 2
A12: Anderson, Teason | B12: Watson | C12: Account Management | D12: Contract | E12: 36375 | G12: 71300 | H12: 5
A13: Andrews, Diane | B13: North | C13: Account Management | D13: Hourly | E13: 36028 | G13: 16688 | H13: 3
A14: Anthony, Robert | B14: Watson | C14: IT | D14: Half-Time | E14: 40393 | F14: DMR | G14: 16925 | H14: 1
A15: Armstrong, David | B15: North | C15: Quality Control | D15: Contract | E15: 35826 | G15: 45030 | H15: 3
A16: Arnold, Cole | B16: North | C16: Sales | D16: Full Time | E16: 40235 | F16: R | G16: 22860 | H16: 5
A17: Ashley, Michael | B17: North | C17: Account Management | D17: Full Time | E17: 40477 | F17: M | G17: 63206 | H17: 1
A18: Atkins, Kevin | B18: North | C18: Manufacturing | D18: Hourly | E18: 35982 | G18: 8904 | H18: 3
A19: Atkinson, Danielle | B19: North | C19: Account Management | D19: Full Time | E19: 37701 | F19: DM | G19: 23560 | H19: 3
A20: Austin, William | B20: Main | C20: Account Management | D20: Full Time | E20: 39335 | F20: DMR | G20: 62688 | H20: 2
A21: Avila, Jody | B21: Main | C21: Quality Assurance | D21: Hourly | E21: 40515 | G21: 33508 | H21: 4
A22: Ayala, Polly | B22: Main | C22: Account Management | D22: Full Time | E22: 39174 | F22: DMR | G22: 23320 | H22: 4
A23: Ayers, Douglas | B23: Main | C23: Manufacturing | D23: Contract | E23: 40462 | G23: 52940 | H23: 4
A24: Bailey, Victor | B24: Watson | C24: Research Center | D24: Full Time | E24: 37684 | F24: R | G24: 42800 | H24: 5
A25: Baker, Barney | B25: Taft | C25: Creative | D25: Contract | E25: 40550 | G25: 80050 | H25: 2
A26: Baldwin, Ray | B26: Watson | C26: Quality Assurance | D26: Full Time | E26: 36514 | F26: R | G26: 48250 | H26: 3
A27: Ball, Kirk | B27: North | C27: Sales | D27: Full Time | E27: 41209 | F27: DM | G27: 87980 | H27: 1
A28: Ballard, Martin | B28: South | C28: IT | D28: Full Time | E28: 39085 | F28: DMR | G28: 87030 | H28: 3
A29: Banks, Ryan | B29: Main | C29: IT | D29: Hourly | E29: 37711 | G29: 21648 | H29: 2
A30: Barber, Robbie | B30: North | C30: Manufacturing | D30: Full Time | E30: 36332 | F30: M | G30: 37760 | H30: 2
A31: Barker, Heidi | B31: West | C31: Account Management | D31: Full Time | E31: 40264 | F31: D | G31: 29760 | H31: 2
A32: Barnes, Grant | B32: Main | C32: Quality Assurance | D32: Hourly | E32: 35861 | G32: 12836 | H32: 5
A33: Barnett, Brenda | B33: North | C33: Human Resources | D33: Full Time | E33: 39683 | F33: DMR | G33: 47350 | H33: 5
A34: Barr, Jennifer | B34: North | C34: Marketing | D34: Full Time | E34: 36116 | F34: D | G34: 49770 | H34: 1
A35: Barrett, John | B35: North | C35: Quality Control | D35: Full Time | E35: 36549 | F35: R | G35: 35460 | H35: 1
A36: Barron, Michael | B36: West | C36: Manufacturing | D36: Full Time | E36: 39655 | F36: D | G36: 34480 | H36: 3
A37: Bartlett, Julia | B37: Watson | C37: Professional Training Group | D37: Full Time | E37: 40818 | F37: M | G37: 44560 | H37: 2
A38: Barton, Barry | B38: North | C38: Professional Training Group | D38: Full Time | E38: 40551 | F38: DMR | G38: 71730 | H38: 1
A39: Bass, Justin | B39: North | C39: Product Development | D39: Contract | E39: 37641 | G39: 31970 | H39: 5
A40: Bates, Verna | B40: North | C40: Manufacturing | D40: Full Time | E40: 37068 | F40: DM | G40: 66010 | H40: 5
...

Sheet Staff table
A1: Names | B1: Building | C1: Department | D1: Status | E1: Hiring date | F1: Benefits | G1: Salary | H1: Rating | I1: Bonus | J1: Taxes | K1: After tax salary | L1: Salary with bonus | S1: Tax | T1: After tax salary | V1: Fixed amt | W1: Tax rate | Y1: Difference | Z1: Actual Tax | AA1: Salary After tax
A2: Tate, Zachary | B2: Taft | C2: Manufacturing | D2: Full Time | E2: 35801 | F2: DMR | G2: 78570 | H2: 1 | I2: =IF(OR(Table2[[#This Row],[Rating]]=4,Table2[[#This Row],[Rating]]=5), 0.05*Table2[[#This Row],[Salary]],0) -> 0 | J2: =VLOOKUP(Table2[[#This Row],[Salary]],'Tax rates'!A$2:C$8, 2) + VLOOKUP(Table2[[#This Row],[Salary]],'Tax rates'!A$2:C$8, 3) * (Table2[[#This Row],[Salary]] - VLOOKUP(Table2[[#This Row],[Salary]],'Tax rates'!A$2:C$8,1)) -> 13224.9 | K2: =Table2[[#This Row],[Salary]]-Table2[[#This Row],[Taxes]] -> 65345.1 | L2: =Table2[[#This Row],[After tax salary]]+Table2[[#This Row],[Bonus]] -> 65345.1 | O2: =VLOOKUP(Table2[[#This Row],[Salary]],'Tax rates'!A1:D8,2) -> 4453.5 | P2: =VLOOKUP(Table2[[#This Row],[Salary]],'Tax rates'!A1:D8,3) -> 0.22 | Q2: =VLOOKUP(Table2[[#This Row],[Salary]],'Tax rates'!A1:D8,1) -> 38700 | R2: =Table2[[#This Row],[Salary]]-Q2 -> 39870 | S2: =O2+P2*R2 -> 13224.9 | T2: =Table2[[#This Row],[Salary]]-S2 -> 65345.1 | V2: =VLOOKUP(Table2[[#This Row],[Salary]],'Tax rates'!A1:D8,2) -> 4453.5 | W2: =VLOOKUP(Table2[[#This Row],[Salary]],'Tax rates'!A1:D8,3) -> 0.22 | X2: =VLOOKUP(Table2[[#This Row],[Salary]],'Tax rates'!A1:D8,1) -> 38700 | Y2: =Table2[[#This Row],[Salary]]-X2 -> 39870 | Z2: =V2+W2*Y2 -> 13224.9 | AA2: =Table2[[#This Row],[Salary]]-Z2 -> 65345.1
A3: Wilcox, Robert | B3: Main | C3: Quality Assurance | D3: Contract | E3: 35806 | G3: 86100 | H3: 4 | I3: =IF(OR(Table2[[#This Row],[Rating]]=4,Table2[[#This Row],[Rating]]=5), 0.05*Table2[[#This Row],[Salary]],0) -> 4305 | J3: =VLOOKUP(Table2[[#This Row],[Salary]],'Tax rates'!A$2:C$8, 2) + VLOOKUP(Table2[[#This Row],[Salary]],'Tax rates'!A$2:C$8, 3) * (Table2[[#This Row],[Salary]] - VLOOKUP(Table2[[#This Row],[Salary]],'Tax rates'!A$2:C$8,1)) -> 14953.5 | K3: =Table2[[#This Row],[Salary]]-Table2[[#This Row],[Taxes]] -> 71146.5 | L3: =Table2[[#This Row],[After tax salary]]+Table2[[#This Row],[Bonus]] -> 75451.5
A4: Baxter, Teresa | B4: Taft | C4: Manufacturing | D4: Half-Time | E4: 35807 | F4: DMR | G4: 48835 | H4: 5 | I4: =IF(OR(Table2[[#This Row],[Rating]]=4,Table2[[#This Row],[Rating]]=5), 0.05*Table2[[#This Row],[Salary]],0) -> 2441.75 | J4: =VLOOKUP(Table2[[#This Row],[Salary]],'Tax rates'!A$2:C$8, 2) + VLOOKUP(Table2[[#This Row],[Salary]],'Tax rates'!A$2:C$8, 3) * (Table2[[#This Row],[Salary]] - VLOOKUP(Table2[[#This Row],[Salary]],'Tax rates'!A$2:C$8,1)) -> 6683.2 | K4: =Table2[[#This Row],[Salary]]-Table2[[#This Row],[Taxes]] -> 42151.8 | L4: =Table2[[#This Row],[After tax salary]]+Table2[[#This Row],[Bonus]] -> 44593.55
A5: Farmer, Suzanne | B5: West | C5: Account Management | D5: Full Time | E5: 35821 | F5: M | G5: 22870 | H5: 3 | I5: =IF(OR(Table2[[#This Row],[Rating]]=4,Table2[[#This Row],[Rating]]=5), 0.05*Table2[[#This Row],[Salary]],0) -> 0 | J5: =VLOOKUP(Table2[[#This Row],[Salary]],'Tax rates'!A$2:C$8, 2) + VLOOKUP(Table2[[#This Row],[Salary]],'Tax rates'!A$2:C$8, 3) * (Table2[[#This Row],[Salary]] - VLOOKUP(Table2[[#This Row],[Salary]],'Tax rates'!A$2:C$8,1)) -> 2553.9 | K5: =Table2[[#This Row],[Salary]]-Table2[[#This Row],[Taxes]] -> 20316.1 | L5: =Table2[[#This Row],[After tax salary]]+Table2[[#This Row],[Bonus]] -> 20316.1
A6: Armstrong, David | B6: North | C6: Quality Control | D6: Contract | E6: 35826 | G6: 45030 | H6: 3 | I6: =IF(OR(Table2[[#This Row],[Rating]]=4,Table2[[#This Row],[Rating]]=5), 0.05*Table2[[#This Row],[Salary]],0) -> 0 | J6: =VLOOKUP(Table2[[#This Row],[Salary]],'Tax rates'!A$2:C$8, 2) + VLOOKUP(Table2[[#This Row],[Salary]],'Tax rates'!A$2:C$8, 3) * (Table2[[#This Row],[Salary]] - VLOOKUP(Table2[[#This Row],[Salary]],'Tax rates'!A$2:C$8,1)) -> 5846.1 | K6: =Table2[[#This Row],[Salary]]-Table2[[#This Row],[Taxes]] -> 39183.9 | L6: =Table2[[#This Row],[After tax salary]]+Table2[[#This Row],[Bonus]] -> 39183.9
A7: Grant, Leonard | B7: South | C7: Account Management | D7: Half-Time | E7: 35826 | F7: DMR | G7: 31205 | H7: 2 | I7: =IF(OR(Table2[[#This Row],[Rating]]=4,Table2[[#This Row],[Rating]]=5), 0.05*Table2[[#This Row],[Salary]],0) -> 0 | J7: =VLOOKUP(Table2[[#This Row],[Salary]],'Tax rates'!A$2:C$8, 2) + VLOOKUP(Table2[[#This Row],[Salary]],'Tax rates'!A$2:C$8, 3) * (Table2[[#This Row],[Salary]] - VLOOKUP(Table2[[#This Row],[Salary]],'Tax rates'!A$2:C$8,1)) -> 3554.1 | K7: =Table2[[#This Row],[Salary]]-Table2[[#This Row],[Taxes]] -> 27650.9 | L7: =Table2[[#This Row],[After tax salary]]+Table2[[#This Row],[Bonus]] -> 27650.9
A8: Powers, Tia | B8: North | C8: Facilities/Engineering | D8: Full Time | E8: 35829 | F8: DMR | G8: 61030 | H8: 3 | I8: =IF(OR(Table2[[#This Row],[Rating]]=4,Table2[[#This Row],[Rating]]=5), 0.05*Table2[[#This Row],[Salary]],0) -> 0 | J8: =VLOOKUP(Table2[[#This Row],[Salary]],'Tax rates'!A$2:C$8, 2) + VLOOKUP(Table2[[#This Row],[Salary]],'Tax rates'!A$2:C$8, 3) * (Table2[[#This Row],[Salary]] - VLOOKUP(Table2[[#This Row],[Salary]],'Tax rates'!A$2:C$8,1)) -> 9366.1 | K8: =Table2[[#This Row],[Salary]]-Table2[[#This Row],[Taxes]] -> 51663.9 | L8: =Table2[[#This Row],[After tax salary]]+Table2[[#This Row],[Bonus]] -> 51663.9
A9: Meyers, David | B9: West | C9: Manufacturing | D9: Hourly | E9: 35829 | G9: 29176 | H9: 3 | I9: =IF(OR(Table2[[#This Row],[Rating]]=4,Table2[[#This Row],[Rating]]=5), 0.05*Table2[[#This Row],[Salary]],0) -> 0 | J9: =VLOOKUP(Table2[[#This Row],[Salary]],'Tax rates'!A$2:C$8, 2) + VLOOKUP(Table2[[#This Row],[Salary]],'Tax rates'!A$2:C$8, 3) * (Table2[[#This Row],[Salary]] - VLOOKUP(Table2[[#This Row],[Salary]],'Tax rates'!A$2:C$8,1)) -> 3310.62 | K9: =Table2[[#This Row],[Salary]]-Table2[[#This Row],[Taxes]] -> 25865.38 | L9: =Table2[[#This Row],[After tax salary]]+Table2[[#This Row],[Bonus]] -> 25865.38
A10: Walker, Mike | B10: Watson | C10: Manufacturing | D10: Full Time | E10: 35830 | F10: M | G10: 35460 | H10: 5 | I10: =IF(OR(Table2[[#This Row],[Rating]]=4,Table2[[#This Row],[Rating]]=5), 0.05*Table2[[#This Row],[Salary]],0) -> 1773 | J10: =VLOOKUP(Table2[[#This Row],[Salary]],'Tax rates'!A$2:C$8, 2) + VLOOKUP(Table2[[#This Row],[Salary]],'Tax rates'!A$2:C$8, 3) * (Table2[[#This Row],[Salary]] - VLOOKUP(Table2[[#This Row],[Salary]],'Tax rates'!A$2:C$8,1)) -> 4064.7 | K10: =Table2[[#This Row],[Salary]]-Table2[[#This Row],[Taxes]] -> 31395.3 | L10: =Table2[[#This Row],[After tax salary]]+Table2[[#This Row],[Bonus]] -> 33168.3
A11: Navarro, Marc | B11: Main | C11: Facilities/Engineering | D11: Half-Time | E11: 35842 | F11: D | G11: 23380 | H11: 4 | I11: =IF(OR(Table2[[#This Row],[Rating]]=4,Table2[[#This Row],[Rating]]=5), 0.05*Table2[[#This Row],[Salary]],0) -> 1169 | J11: =VLOOKUP(Table2[[#This Row],[Salary]],'Tax rates'!A$2:C$8, 2) + VLOOKUP(Table2[[#This Row],[Salary]],'Tax rates'!A$2:C$8, 3) * (Table2[[#This Row],[Salary]] - VLOOKUP(Table2[[#This Row],[Salary]],'Tax rates'!A$2:C$8,1)) -> 2615.1 | K11: =Table2[[#This Row],[Salary]]-Table2[[#This Row],[Taxes]] -> 20764.9 | L11: =Table2[[#This Row],[After tax salary]]+Table2[[#This Row],[Bonus]] -> 21933.9
A12: Pugh, Lawrence | B12: South | C12: Quality Assurance | D12: Half-Time | E12: 35842 | F12: M | G12: 39530 | H12: 5 | I12: =IF(OR(Table2[[#This Row],[Rating]]=4,Table2[[#This Row],[Rating]]=5), 0.05*Table2[[#This Row],[Salary]],0) -> 1976.5 | J12: =VLOOKUP(Table2[[#This Row],[Salary]],'Tax rates'!A$2:C$8, 2) + VLOOKUP(Table2[[#This Row],[Salary]],'Tax rates'!A$2:C$8, 3) * (Table2[[#This Row],[Salary]] - VLOOKUP(Table2[[#This Row],[Salary]],'Tax rates'!A$2:C$8,1)) -> 4636.1 | K12: =Table2[[#This Row],[Salary]]-Table2[[#This Row],[Taxes]] -> 34893.9 | L12: =Table2[[#This Row],[After tax salary]]+Table2[[#This Row],[Bonus]] -> 36870.4
A13: Briggs, Bryan | B13: Main | C13: Facilities/Engineering | D13: Contract | E13: 35848 | G13: 85480 | H13: 5 | I13: =IF(OR(Table2[[#This Row],[Rating]]=4,Table2[[#This Row],[Rating]]=5), 0.05*Table2[[#This Row],[Salary]],0) -> 4274 | J13: =VLOOKUP(Table2[[#This Row],[Salary]],'Tax rates'!A$2:C$8, 2) + VLOOKUP(Table2[[#This Row],[Salary]],'Tax rates'!A$2:C$8, 3) * (Table2[[#This Row],[Salary]] - VLOOKUP(Table2[[#This Row],[Salary]],'Tax rates'!A$2:C$8,1)) -> 14804.7 | K13: =Table2[[#This Row],[Salary]]-Table2[[#This Row],[Taxes]] -> 70675.3 | L13: =Table2[[#This Row],[After tax salary]]+Table2[[#This Row],[Bonus]] -> 74949.3
A14: Patton, Corey | B14: West | C14: Marketing | D14: Full Time | E14: 35856 | F14: D | G14: 86830 | H14: 3 | I14: =IF(OR(Table2[[#This Row],[Rating]]=4,Table2[[#This Row],[Rating]]=5), 0.05*Table2[[#This Row],[Salary]],0) -> 0 | J14: =VLOOKUP(Table2[[#This Row],[Salary]],'Tax rates'!A$2:C$8, 2) + VLOOKUP(Table2[[#This Row],[Salary]],'Tax rates'!A$2:C$8, 3) * (Table2[[#This Row],[Salary]] - VLOOKUP(Table2[[#This Row],[Salary]],'Tax rates'!A$2:C$8,1)) -> 15128.7 | K14: =Table2[[#This Row],[Salary]]-Table2[[#This Row],[Taxes]] -> 71701.3 | L14: =Table2[[#This Row],[After tax salary]]+Table2[[#This Row],[Bonus]] -> 71701.3
A15: Chavez, Thomas | B15: Main | C15: Marketing | D15: Full Time | E15: 35857 | F15: R | G15: 82110 | H15: 3 | I15: =IF(OR(Table2[[#This Row],[Rating]]=4,Table2[[#This Row],[Rating]]=5), 0.05*Table2[[#This Row],[Salary]],0) -> 0 | J15: =VLOOKUP(Table2[[#This Row],[Salary]],'Tax rates'!A$2:C$8, 2) + VLOOKUP(Table2[[#This Row],[Salary]],'Tax rates'!A$2:C$8, 3) * (Table2[[#This Row],[Salary]] - VLOOKUP(Table2[[#This Row],[Salary]],'Tax rates'!A$2:C$8,1)) -> 14003.7 | K15: =Table2[[#This Row],[Salary]]-Table2[[#This Row],[Taxes]] -> 68106.3 | L15: =Table2[[#This Row],[After tax salary]]+Table2[[#This Row],[Bonus]] -> 68106.3
A16: Barnes, Grant | B16: Main | C16: Quality Assurance | D16: Hourly | E16: 35861 | G16: 12836 | H16: 5 | I16: =IF(OR(Table2[[#This Row],[Rating]]=4,Table2[[#This Row],[Rating]]=5), 0.05*Table2[[#This Row],[Salary]],0) -> 641.8 | J16: =VLOOKUP(Table2[[#This Row],[Salary]],'Tax rates'!A$2:C$8, 2) + VLOOKUP(Table2[[#This Row],[Salary]],'Tax rates'!A$2:C$8, 3) * (Table2[[#This Row],[Salary]] - VLOOKUP(Table2[[#This Row],[Salary]],'Tax rates'!A$2:C$8,1)) -> 1349.82 | K16: =Table2[[#This Row],[Salary]]-Table2[[#This Row],[Taxes]] -> 11486.18 | L16: =Table2[[#This Row],[After tax salary]]+Table2[[#This Row],[Bonus]] -> 12127.98
A17: Turner, Ray | B17: West | C17: Quality Assurance | D17: Hourly | E17: 35869 | G17: 17912 | H17: 5 | I17: =IF(OR(Table2[[#This Row],[Rating]]=4,Table2[[#This Row],[Rating]]=5), 0.05*Table2[[#This Row],[Salary]],0) -> 895.6 | J17: =VLOOKUP(Table2[[#This Row],[Salary]],'Tax rates'!A$2:C$8, 2) + VLOOKUP(Table2[[#This Row],[Salary]],'Tax rates'!A$2:C$8, 3) * (Table2[[#This Row],[Salary]] - VLOOKUP(Table2[[#This Row],[Salary]],'Tax rates'!A$2:C$8,1)) -> 1958.94 | K17: =Table2[[#This Row],[Salary]]-Table2[[#This Row],[Taxes]] -> 15953.06 | L17: =Table2[[#This Row],[After tax salary]]+Table2[[#This Row],[Bonus]] -> 16848.66
A18: Henry, Craig | B18: North | C18: Quality Assurance | D18: Full Time | E18: 35896 | F18: R | G18: 70280 | H18: 3 | I18: =IF(OR(Table2[[#This Row],[Rating]]=4,Table2[[#This Row],[Rating]]=5), 0.05*Table2[[#This Row],[Salary]],0) -> 0 | J18: =VLOOKUP(Table2[[#This Row],[Salary]],'Tax rates'!A$2:C$8, 2) + VLOOKUP(Table2[[#This Row],[Salary]],'Tax rates'!A$2:C$8, 3) * (Table2[[#This Row],[Salary]] - VLOOKUP(Table2[[#This Row],[Salary]],'Tax rates'!A$2:C$8,1)) -> 11401.1 | K18: =Table2[[#This Row],[Salary]]-Table2[[#This Row],[Taxes]] -> 58878.9 | L18: =Table2[[#This Row],[After tax salary]]+Table2[[#This Row],[Bonus]] -> 58878.9
A19: Lawrence, Ronald | B19: Main | C19: Facilities/Engineering | D19: Contract | E19: 35902 | G19: 63340 | H19: 3 | I19: =IF(OR(Table2[[#This Row],[Rating]]=4,Table2[[#This Row],[Rating]]=5), 0.05*Table2[[#This Row],[Salary]],0) -> 0 | J19: =VLOOKUP(Table2[[#This Row],[Salary]],'Tax rates'!A$2:C$8, 2) + VLOOKUP(Table2[[#This Row],[Salary]],'Tax rates'!A$2:C$8, 3) * (Table2[[#This Row],[Salary]] - VLOOKUP(Table2[[#This Row],[Salary]],'Tax rates'!A$2:C$8,1)) -> 9874.3 | K19: =Table2[[#This Row],[Salary]]-Table2[[#This Row],[Taxes]] -> 53465.7 | L19: =Table2[[#This Row],[After tax salary]]+Table2[[#This Row],[Bonus]] -> 53465.7
A20: Garrison, Chris | B20: North | C20: IT | D20: Full Time | E20: 35903 | F20: DMR | G20: 68520 | H20: 5 | I20: =IF(OR(Table2[[#This Row],[Rating]]=4,Table2[[#This Row],[Rating]]=5), 0.05*Table2[[#This Row],[Salary]],0) -> 3426 | J20: =VLOOKUP(Table2[[#This Row],[Salary]],'Tax rates'!A$2:C$8, 2) + VLOOKUP(Table2[[#This Row],[Salary]],'Tax rates'!A$2:C$8, 3) * (Table2[[#This Row],[Salary]] - VLOOKUP(Table2[[#This Row],[Salary]],'Tax rates'!A$2:C$8,1)) -> 11013.9 | K20: =Table2[[#This Row],[Salary]]-Table2[[#This Row],[Taxes]] -> 57506.1 | L20: =Table2[[#This Row],[After tax salary]]+Table2[[#This Row],[Bonus]] -> 60932.1
A21: Jefferson, Elaine | B21: Taft | C21: Account Management | D21: Full Time | E21: 35918 | F21: DM | G21: 73740 | H21: 4 | I21: =IF(OR(Table2[[#This Row],[Rating]]=4,Table2[[#This Row],[Rating]]=5), 0.05*Table2[[#This Row],[Salary]],0) -> 3687 | J21: =VLOOKUP(Table2[[#This Row],[Salary]],'Tax rates'!A$2:C$8, 2) + VLOOKUP(Table2[[#This Row],[Salary]],'Tax rates'!A$2:C$8, 3) * (Table2[[#This Row],[Salary]] - VLOOKUP(Table2[[#This Row],[Salary]],'Tax rates'!A$2:C$8,1)) -> 12162.3 | K21: =Table2[[#This Row],[Salary]]-Table2[[#This Row],[Taxes]] -> 61577.7 | L21: =Table2[[#This Row],[After tax salary]]+Table2[[#This Row],[Bonus]] -> 65264.7
A22: Dudley, James | B22: South | C22: IT | D22: Contract | E22: 35921 | G22: 63330 | H22: 4 | I22: =IF(OR(Table2[[#This Row],[Rating]]=4,Table2[[#This Row],[Rating]]=5), 0.05*Table2[[#This Row],[Salary]],0) -> 3166.5 | J22: =VLOOKUP(Table2[[#This Row],[Salary]],'Tax rates'!A$2:C$8, 2) + VLOOKUP(Table2[[#This Row],[Salary]],'Tax rates'!A$2:C$8, 3) * (Table2[[#This Row],[Salary]] - VLOOKUP(Table2[[#This Row],[Salary]],'Tax rates'!A$2:C$8,1)) -> 9872.1 | K22: =Table2[[#This Row],[Salary]]-Table2[[#This Row],[Taxes]] -> 53457.9 | L22: =Table2[[#This Row],[After tax salary]]+Table2[[#This Row],[Bonus]] -> 56624.4
A23: Fields, Cathy | B23: Taft | C23: Manufacturing | D23: Contract | E23: 35927 | G23: 76910 | H23: 1 | I23: =IF(OR(Table2[[#This Row],[Rating]]=4,Table2[[#This Row],[Rating]]=5), 0.05*Table2[[#This Row],[Salary]],0) -> 0 | J23: =VLOOKUP(Table2[[#This Row],[Salary]],'Tax rates'!A$2:C$8, 2) + VLOOKUP(Table2[[#This Row],[Salary]],'Tax rates'!A$2:C$8, 3) * (Table2[[#This Row],[Salary]] - VLOOKUP(Table2[[#This Row],[Salary]],'Tax rates'!A$2:C$8,1)) -> 12859.7 | K23: =Table2[[#This Row],[Salary]]-Table2[[#This Row],[Taxes]] -> 64050.3 | L23: =Table2[[#This Row],[After tax salary]]+Table2[[#This Row],[Bonus]] -> 64050.3
A24: Burgess, Cherie | B24: North | C24: Manufacturing | D24: Full Time | E24: 35932 | F24: R | G24: 89740 | H24: 5 | I24: =IF(OR(Table2[[#This Row],[Rating]]=4,Table2[[#This Row],[Rating]]=5), 0.05*Table2[[#This Row],[Salary]],0) -> 4487 | J24: =VLOOKUP(Table2[[#This Row],[Salary]],'Tax rates'!A$2:C$8, 2) + VLOOKUP(Table2[[#This Row],[Salary]],'Tax rates'!A$2:C$8, 3) * (Table2[[#This Row],[Salary]] - VLOOKUP(Table2[[#This Row],[Salary]],'Tax rates'!A$2:C$8,1)) -> 15827.1 | K24: =Table2[[#This Row],[Salary]]-Table2[[#This Row],[Taxes]] -> 73912.9 | L24: =Table2[[#This Row],[After tax salary]]+Table2[[#This Row],[Bonus]] -> 78399.9
A25: Melton, Scott | B25: West | C25: Manufacturing | D25: Full Time | E25: 35938 | F25: M | G25: 55450 | H25: 5 | I25: =IF(OR(Table2[[#This Row],[Rating]]=4,Table2[[#This Row],[Rating]]=5), 0.05*Table2[[#This Row],[Salary]],0) -> 2772.5 | J25: =VLOOKUP(Table2[[#This Row],[Salary]],'Tax rates'!A$2:C$8, 2) + VLOOKUP(Table2[[#This Row],[Salary]],'Tax rates'!A$2:C$8, 3) * (Table2[[#This Row],[Salary]] - VLOOKUP(Table2[[#This Row],[Salary]],'Tax rates'!A$2:C$8,1)) -> 8138.5 | K25: =Table2[[#This Row],[Salary]]-Table2[[#This Row],[Taxes]] -> 47311.5 | L25: =Table2[[#This Row],[After tax salary]]+Table2[[#This Row],[Bonus]] -> 50084
A26: Gallegos, Rick | B26: Main | C26: Product Development | D26: Contract | E26: 35939 | G26: 25120 | H26: 5 | I26: =IF(OR(Table2[[#This Row],[Rating]]=4,Table2[[#This Row],[Rating]]=5), 0.05*Table2[[#This Row],[Salary]],0) -> 1256 | J26: =VLOOKUP(Table2[[#This Row],[Salary]],'Tax rates'!A$2:C$8, 2) + VLOOKUP(Table2[[#This Row],[Salary]],'Tax rates'!A$2:C$8, 3) * (Table2[[#This Row],[Salary]] - VLOOKUP(Table2[[#This Row],[Salary]],'Tax rates'!A$2:C$8,1)) -> 2823.9 | K26: =Table2[[#This Row],[Salary]]-Table2[[#This Row],[Taxes]] -> 22296.1 | L26: =Table2[[#This Row],[After tax salary]]+Table2[[#This Row],[Bonus]] -> 23552.1
A27: Wallace, Timothy | B27: Watson | C27: Facilities/Engineering | D27: Contract | E27: 35940 | G27: 88000 | H27: 5 | I27: =IF(OR(Table2[[#This Row],[Rating]]=4,Table2[[#This Row],[Rating]]=5), 0.05*Table2[[#This Row],[Salary]],0) -> 4400 | J27: =VLOOKUP(Table2[[#This Row],[Salary]],'Tax rates'!A$2:C$8, 2) + VLOOKUP(Table2[[#This Row],[Salary]],'Tax rates'!A$2:C$8, 3) * (Table2[[#This Row],[Salary]] - VLOOKUP(Table2[[#This Row],[Salary]],'Tax rates'!A$2:C$8,1)) -> 15409.5 | K27: =Table2[[#This Row],[Salary]]-Table2[[#This Row],[Taxes]] -> 72590.5 | L27: =Table2[[#This Row],[After tax salary]]+Table2[[#This Row],[Bonus]] -> 76990.5
A28: Booth, Raquel | B28: West | C28: Account Management | D28: Hourly | E28: 35946 | G28: 14332 | H28: 5 | I28: =IF(OR(Table2[[#This Row],[Rating]]=4,Table2[[#This Row],[Rating]]=5), 0.05*Table2[[#This Row],[Salary]],0) -> 716.6 | J28: =VLOOKUP(Table2[[#This Row],[Salary]],'Tax rates'!A$2:C$8, 2) + VLOOKUP(Table2[[#This Row],[Salary]],'Tax rates'!A$2:C$8, 3) * (Table2[[#This Row],[Salary]] - VLOOKUP(Table2[[#This Row],[Salary]],'Tax rates'!A$2:C$8,1)) -> 1529.34 | K28: =Table2[[#This Row],[Salary]]-Table2[[#This Row],[Taxes]] -> 12802.66 | L28: =Table2[[#This Row],[After tax salary]]+Table2[[#This Row],[Bonus]] -> 13519.26
A29: Jackson, Eric | B29: North | C29: Account Management | D29: Full Time | E29: 35958 | F29: R | G29: 61420 | H29: 4 | I29: =IF(OR(Table2[[#This Row],[Rating]]=4,Table2[[#This Row],[Rating]]=5), 0.05*Table2[[#This Row],[Salary]],0) -> 3071 | J29: =VLOOKUP(Table2[[#This Row],[Salary]],'Tax rates'!A$2:C$8, 2) + VLOOKUP(Table2[[#This Row],[Salary]],'Tax rates'!A$2:C$8, 3) * (Table2[[#This Row],[Salary]] - VLOOKUP(Table2[[#This Row],[Salary]],'Tax rates'!A$2:C$8,1)) -> 9451.9 | K29: =Table2[[#This Row],[Salary]]-Table2[[#This Row],[Taxes]] -> 51968.1 | L29: =Table2[[#This Row],[After tax salary]]+Table2[[#This Row],[Bonus]] -> 55039.1
A30: Roberson, Eileen | B30: Main | C30: Creative | D30: Contract | E30: 35959 | G30: 64470 | H30: 3 | I30: =IF(OR(Table2[[#This Row],[Rating]]=4,Table2[[#This Row],[Rating]]=5), 0.05*Table2[[#This Row],[Salary]],0) -> 0 | J30: =VLOOKUP(Table2[[#This Row],[Salary]],'Tax rates'!A$2:C$8, 2) + VLOOKUP(Table2[[#This Row],[Salary]],'Tax rates'!A$2:C$8, 3) * (Table2[[#This Row],[Salary]] - VLOOKUP(Table2[[#This Row],[Salary]],'Tax rates'!A$2:C$8,1)) -> 10122.9 | K30: =Table2[[#This Row],[Salary]]-Table2[[#This Row],[Taxes]] -> 54347.1 | L30: =Table2[[#This Row],[After tax salary]]+Table2[[#This Row],[Bonus]] -> 54347.1
A31: Owen, Robert | B31: Main | C31: Sales | D31: Half-Time | E31: 35961 | F31: DMR | G31: 20500 | H31: 3 | I31: =IF(OR(Table2[[#This Row],[Rating]]=4,Table2[[#This Row],[Rating]]=5), 0.05*Table2[[#This Row],[Salary]],0) -> 0 | J31: =VLOOKUP(Table2[[#This Row],[Salary]],'Tax rates'!A$2:C$8, 2) + VLOOKUP(Table2[[#This Row],[Salary]],'Tax rates'!A$2:C$8, 3) * (Table2[[#This Row],[Salary]] - VLOOKUP(Table2[[#This Row],[Salary]],'Tax rates'!A$2:C$8,1)) -> 2269.5 | K31: =Table2[[#This Row],[Salary]]-Table2[[#This Row],[Taxes]] -> 18230.5 | L31: =Table2[[#This Row],[After tax salary]]+Table2[[#This Row],[Bonus]] -> 18230.5
A32: Harding, Erin | B32: West | C32: Facilities/Engineering | D32: Full Time | E32: 35965 | F32: M | G32: 34780 | H32: 4 | I32: =IF(OR(Table2[[#This Row],[Rating]]=4,Table2[[#This Row],[Rating]]=5), 0.05*Table2[[#This Row],[Salary]],0) -> 1739 | J32: =VLOOKUP(Table2[[#This Row],[Salary]],'Tax rates'!A$2:C$8, 2) + VLOOKUP(Table2[[#This Row],[Salary]],'Tax rates'!A$2:C$8, 3) * (Table2[[#This Row],[Salary]] - VLOOKUP(Table2[[#This Row],[Salary]],'Tax rates'!A$2:C$8,1)) -> 3983.1 | K32: =Table2[[#This Row],[Salary]]-Table2[[#This Row],[Taxes]] -> 30796.9 | L32: =Table2[[#This Row],[After tax salary]]+Table2[[#This Row],[Bonus]] -> 32535.9
A33: Russell, Mark | B33: Main | C33: IT | D33: Full Time | E33: 35969 | F33: DMR | G33: 74530 | H33: 5 | I33: =IF(OR(Table2[[#This Row],[Rating]]=4,Table2[[#This Row],[Rating]]=5), 0.05*Table2[[#This Row],[Salary]],0) -> 3726.5 | J33: =VLOOKUP(Table2[[#This Row],[Salary]],'Tax rates'!A$2:C$8, 2) + VLOOKUP(Table2[[#This Row],[Salary]],'Tax rates'!A$2:C$8, 3) * (Table2[[#This Row],[Salary]] - VLOOKUP(Table2[[#This Row],[Salary]],'Tax rates'!A$2:C$8,1)) -> 12336.1 | K33: =Table2[[#This Row],[Salary]]-Table2[[#This Row],[Taxes]] -> 62193.9 | L33: =Table2[[#This Row],[After tax salary]]+Table2[[#This Row],[Bonus]] -> 65920.4
A34: Bradford, Raymond | B34: North | C34: Manufacturing | D34: Contract | E34: 35972 | G34: 71710 | H34: 5 | I34: =IF(OR(Table2[[#This Row],[Rating]]=4,Table2[[#This Row],[Rating]]=5), 0.05*Table2[[#This Row],[Salary]],0) -> 3585.5 | J34: =VLOOKUP(Table2[[#This Row],[Salary]],'Tax rates'!A$2:C$8, 2) + VLOOKUP(Table2[[#This Row],[Salary]],'Tax rates'!A$2:C$8, 3) * (Table2[[#This Row],[Salary]] - VLOOKUP(Table2[[#This Row],[Salary]],'Tax rates'!A$2:C$8,1)) -> 11715.7 | K34: =Table2[[#This Row],[Salary]]-Table2[[#This Row],[Taxes]] -> 59994.3 | L34: =Table2[[#This Row],[After tax salary]]+Table2[[#This Row],[Bonus]] -> 63579.8
A35: Atkins, Kevin | B35: North | C35: Manufacturing | D35: Hourly | E35: 35982 | G35: 8904 | H35: 3 | I35: =IF(OR(Table2[[#This Row],[Rating]]=4,Table2[[#This Row],[Rating]]=5), 0.05*Table2[[#This Row],[Salary]],0) -> 0 | J35: =VLOOKUP(Table2[[#This Row],[Salary]],'Tax rates'!A$2:C$8, 2) + VLOOKUP(Table2[[#This Row],[Salary]],'Tax rates'!A$2:C$8, 3) * (Table2[[#This Row],[Salary]] - VLOOKUP(Table2[[#This Row],[Salary]],'Tax rates'!A$2:C$8,1)) -> 890.4 | K35: =Table2[[#This Row],[Salary]]-Table2[[#This Row],[Taxes]] -> 8013.6 | L35: =Table2[[#This Row],[After tax salary]]+Table2[[#This Row],[Bonus]] -> 8013.6
A36: Santos, Garret | B36: Taft | C36: Product Development | D36: Full Time | E36: 35989 | F36: DM | G36: 71010 | H36: 5 | I36: =IF(OR(Table2[[#This Row],[Rating]]=4,Table2[[#This Row],[Rating]]=5), 0.05*Table2[[#This Row],[Salary]],0) -> 3550.5 | J36: =VLOOKUP(Table2[[#This Row],[Salary]],'Tax rates'!A$2:C$8, 2) + VLOOKUP(Table2[[#This Row],[Salary]],'Tax rates'!A$2:C$8, 3) * (Table2[[#This Row],[Salary]] - VLOOKUP(Table2[[#This Row],[Salary]],'Tax rates'!A$2:C$8,1)) -> 11561.7 | K36: =Table2[[#This Row],[Salary]]-Table2[[#This Row],[Taxes]] -> 59448.3 | L36: =Table2[[#This Row],[After tax salary]]+Table2[[#This Row],[Bonus]] -> 62998.8
A37: Preston, Chris | B37: Main | C37: Account Management | D37: Full Time | E37: 35990 | F37: D | G37: 36890 | H37: 1 | I37: =IF(OR(Table2[[#This Row],[Rating]]=4,Table2[[#This Row],[Rating]]=5), 0.05*Table2[[#This Row],[Salary]],0) -> 0 | J37: =VLOOKUP(Table2[[#This Row],[Salary]],'Tax rates'!A$2:C$8, 2) + VLOOKUP(Table2[[#This Row],[Salary]],'Tax rates'!A$2:C$8, 3) * (Table2[[#This Row],[Salary]] - VLOOKUP(Table2[[#This Row],[Salary]],'Tax rates'!A$2:C$8,1)) -> 4236.3 | K37: =Table2[[#This Row],[Salary]]-Table2[[#This Row],[Taxes]] -> 32653.7 | L37: =Table2[[#This Row],[After tax salary]]+Table2[[#This Row],[Bonus]] -> 32653.7
A38: Chambers, Richard | B38: Main | C38: Manufacturing | D38: Contract | E38: 35992 | G38: 68260 | H38: 5 | I38: =IF(OR(Table2[[#This Row],[Rating]]=4,Table2[[#This Row],[Rating]]=5), 0.05*Table2[[#This Row],[Salary]],0) -> 3413 | J38: =VLOOKUP(Table2[[#This Row],[Salary]],'Tax rates'!A$2:C$8, 2) + VLOOKUP(Table2[[#This Row],[Salary]],'Tax rates'!A$2:C$8, 3) * (Table2[[#This Row],[Salary]] - VLOOKUP(Table2[[#This Row],[Salary]],'Tax rates'!A$2:C$8,1)) -> 10956.7 | K38: =Table2[[#This Row],[Salary]]-Table2[[#This Row],[Taxes]] -> 57303.3 | L38: =Table2[[#This Row],[After tax salary]]+Table2[[#This Row],[Bonus]] -> 60716.3
A39: Jacobs, Florianne | B39: Main | C39: Manufacturing | D39: Full Time | E39: 35996 | F39: DMR | G39: 40340 | H39: 2 | I39: =IF(OR(Table2[[#This Row],[Rating]]=4,Table2[[#This Row],[Rating]]=5), 0.05*Table2[[#This Row],[Salary]],0) -> 0 | J39: =VLOOKUP(Table2[[#This Row],[Salary]],'Tax rates'!A$2:C$8, 2) + VLOOKUP(Table2[[#This Row],[Salary]],'Tax rates'!A$2:C$8, 3) * (Table2[[#This Row],[Salary]] - VLOOKUP(Table2[[#This Row],[Salary]],'Tax rates'!A$2:C$8,1)) -> 4814.3 | K39: =Table2[[#This Row],[Salary]]-Table2[[#This Row],[Taxes]] -> 35525.7 | L39: =Table2[[#This Row],[After tax salary]]+Table2[[#This Row],[Bonus]] -> 35525.7
A40: Wilkinson, Gregory | B40: North | C40: Manufacturing | D40: Contract | E40: 35997 | G40: 72520 | H40: 3 | I40: =IF(OR(Table2[[#This Row],[Rating]]=4,Table2[[#This Row],[Rating]]=5), 0.05*Table2[[#This Row],[Salary]],0) -> 0 | J40: =VLOOKUP(Table2[[#This Row],[Salary]],'Tax rates'!A$2:C$8, 2) + VLOOKUP(Table2[[#This Row],[Salary]],'Tax rates'!A$2:C$8, 3) * (Table2[[#This Row],[Salary]] - VLOOKUP(Table2[[#This Row],[Salary]],'Tax rates'!A$2:C$8,1)) -> 11893.9 | K40: =Table2[[#This Row],[Salary]]-Table2[[#This Row],[Taxes]] -> 60626.1 | L40: =Table2[[#This Row],[After tax salary]]+Table2[[#This Row],[Bonus]] -> 60626.1
...

Sheet Tax rates
A1: Salary greater or equal than | B1: Fixed amount | C1: Percentage | D1: Of the difference with
A2: 0 | B2: 0 | C2: 0.1 | D2: 0
A3: 9525 | B3: 952.5 | C3: 0.12 | D3: =A3 -> 9525
A4: 38700 | B4: 4453.5 | C4: 0.22 | D4: =A4 -> 38700
A5: 82500 | B5: 14089.5 | C5: 0.24 | D5: =A5 -> 82500
A6: 157500 | B6: 32089.5 | C6: 0.32 | D6: =A6 -> 157500
A7: 200000 | B7: 45689.5 | C7: 0.35 | D7: =A7 -> 200000
A8: 500000 | B8: 150689.5 | C8: 0.37 | D8: =A8 -> 500000

Sheet With data validation
A1: Names | B1: Building | C1: Department | D1: Status | E1: Hiring date | F1: Benefits | G1: Salary | H1: Rating | I1: Bonus | J1: Taxes | K1: After tax salary
A2: Disha | B2: Watson | C2: IT | L2: <-insert data here to see the data validation
A3: Burnett, Kevin | B3: Main | C3: Account Management | D3: Full Time | E3: 40624 | F3: D | G3: 86500 | H3: 1 | I3: =IF(OR(Table24[[#This Row],[Rating]]=4,Table24[[#This Row],[Rating]]=5), 0.05*Table24[[#This Row],[Salary]],0) -> 0 | J3: =VLOOKUP(Table24[[#This Row],[Salary]],'Tax rates'!A$2:C$8, 2) + VLOOKUP(Table24[[#This Row],[Salary]],'Tax rates'!A$2:C$8, 3) * (Table24[[#This Row],[Salary]] - VLOOKUP(Table24[[#This Row],[Salary]],'Tax rates'!A$2:C$8,1)) -> 15049.5 | K3: =Table24[[#This Row],[Salary]]-Table24[[#This Row],[Taxes]] -> 71450.5
A4: Herrera, Shawn | B4: Main | C4: Account Management | D4: Full Time | E4: 40831 | F4: M | G4: 79400 | H4: 4 | I4: =IF(OR(Table24[[#This Row],[Rating]]=4,Table24[[#This Row],[Rating]]=5), 0.05*Table24[[#This Row],[Salary]],0) -> 3970 | J4: =VLOOKUP(Table24[[#This Row],[Salary]],'Tax rates'!A$2:C$8, 2) + VLOOKUP(Table24[[#This Row],[Salary]],'Tax rates'!A$2:C$8, 3) * (Table24[[#This Row],[Salary]] - VLOOKUP(Table24[[#This Row],[Salary]],'Tax rates'!A$2:C$8,1)) -> 13407.5 | K4: =Table24[[#This Row],[Salary]]-Table24[[#This Row],[Taxes]] -> 65992.5
A5: Roman, Teri | B5: Main | C5: Account Management | D5: Contract | E5: 40707 | G5: 79380 | H5: 1 | I5: =IF(OR(Table24[[#This Row],[Rating]]=4,Table24[[#This Row],[Rating]]=5), 0.05*Table24[[#This Row],[Salary]],0) -> 0 | J5: =VLOOKUP(Table24[[#This Row],[Salary]],'Tax rates'!A$2:C$8, 2) + VLOOKUP(Table24[[#This Row],[Salary]],'Tax rates'!A$2:C$8, 3) * (Table24[[#This Row],[Salary]] - VLOOKUP(Table24[[#This Row],[Salary]],'Tax rates'!A$2:C$8,1)) -> 13403.1 | K5: =Table24[[#This Row],[Salary]]-Table24[[#This Row],[Taxes]] -> 65976.9
A6: William, William | B6: Main | C6: Account Management | D6: Full Time | E6: 40765 | F6: M | G6: 77740 | H6: 1 | I6: =IF(OR(Table24[[#This Row],[Rating]]=4,Table24[[#This Row],[Rating]]=5), 0.05*Table24[[#This Row],[Salary]],0) -> 0 | J6: =VLOOKUP(Table24[[#This Row],[Salary]],'Tax rates'!A$2:C$8, 2) + VLOOKUP(Table24[[#This Row],[Salary]],'Tax rates'!A$2:C$8, 3) * (Table24[[#This Row],[Salary]] - VLOOKUP(Table24[[#This Row],[Salary]],'Tax rates'!A$2:C$8,1)) -> 13042.3 | K6: =Table24[[#This Row],[Salary]]-Table24[[#This Row],[Taxes]] -> 64697.7
A7: Lawson, Erin | B7: Main | C7: Account Management | D7: Full Time | E7: 39282 | F7: M | G7: 69420 | H7: 2 | I7: =IF(OR(Table24[[#This Row],[Rating]]=4,Table24[[#This Row],[Rating]]=5), 0.05*Table24[[#This Row],[Salary]],0) -> 0 | J7: =VLOOKUP(Table24[[#This Row],[Salary]],'Tax rates'!A$2:C$8, 2) + VLOOKUP(Table24[[#This Row],[Salary]],'Tax rates'!A$2:C$8, 3) * (Table24[[#This Row],[Salary]] - VLOOKUP(Table24[[#This Row],[Salary]],'Tax rates'!A$2:C$8,1)) -> 11211.9 | K7: =Table24[[#This Row],[Salary]]-Table24[[#This Row],[Taxes]] -> 58208.1
A8: Vargas, Bryant | B8: Main | C8: Account Management | D8: Full Time | E8: 36393 | F8: R | G8: 65910 | H8: 5 | I8: =IF(OR(Table24[[#This Row],[Rating]]=4,Table24[[#This Row],[Rating]]=5), 0.05*Table24[[#This Row],[Salary]],0) -> 3295.5 | J8: =VLOOKUP(Table24[[#This Row],[Salary]],'Tax rates'!A$2:C$8, 2) + VLOOKUP(Table24[[#This Row],[Salary]],'Tax rates'!A$2:C$8, 3) * (Table24[[#This Row],[Salary]] - VLOOKUP(Table24[[#This Row],[Salary]],'Tax rates'!A$2:C$8,1)) -> 10439.7 | K8: =Table24[[#This Row],[Salary]]-Table24[[#This Row],[Taxes]] -> 55470.3
A9: Reid, Elizabeth | B9: Main | C9: Account Management | D9: Full Time | E9: 39047 | F9: R | G9: 65880 | H9: 5 | I9: =IF(OR(Table24[[#This Row],[Rating]]=4,Table24[[#This Row],[Rating]]=5), 0.05*Table24[[#This Row],[Salary]],0) -> 3294 | J9: =VLOOKUP(Table24[[#This Row],[Salary]],'Tax rates'!A$2:C$8, 2) + VLOOKUP(Table24[[#This Row],[Salary]],'Tax rates'!A$2:C$8, 3) * (Table24[[#This Row],[Salary]] - VLOOKUP(Table24[[#This Row],[Salary]],'Tax rates'!A$2:C$8,1)) -> 10433.1 | K9: =Table24[[#This Row],[Salary]]-Table24[[#This Row],[Taxes]] -> 55446.9
A10: Austin, William | B10: Main | C10: Account Management | D10: Full Time | E10: 39335 | F10: DMR | G10: 62688 | H10: 2 | I10: =IF(OR(Table24[[#This Row],[Rating]]=4,Table24[[#This Row],[Rating]]=5), 0.05*Table24[[#This Row],[Salary]],0) -> 0 | J10: =VLOOKUP(Table24[[#This Row],[Salary]],'Tax rates'!A$2:C$8, 2) + VLOOKUP(Table24[[#This Row],[Salary]],'Tax rates'!A$2:C$8, 3) * (Table24[[#This Row],[Salary]] - VLOOKUP(Table24[[#This Row],[Salary]],'Tax rates'!A$2:C$8,1)) -> 9730.86 | K10: =Table24[[#This Row],[Salary]]-Table24[[#This Row],[Taxes]] -> 52957.14
A11: Hayes, Edward | B11: Main | C11: Account Management | D11: Full Time | E11: 36536 | F11: DMR | G11: 62400 | H11: 4 | I11: =IF(OR(Table24[[#This Row],[Rating]]=4,Table24[[#This Row],[Rating]]=5), 0.05*Table24[[#This Row],[Salary]],0) -> 3120 | J11: =VLOOKUP(Table24[[#This Row],[Salary]],'Tax rates'!A$2:C$8, 2) + VLOOKUP(Table24[[#This Row],[Salary]],'Tax rates'!A$2:C$8, 3) * (Table24[[#This Row],[Salary]] - VLOOKUP(Table24[[#This Row],[Salary]],'Tax rates'!A$2:C$8,1)) -> 9667.5 | K11: =Table24[[#This Row],[Salary]]-Table24[[#This Row],[Taxes]] -> 52732.5
A12: Vasquez, Michael | B12: Main | C12: Account Management | D12: Contract | E12: 37404 | G12: 60070 | H12: 3 | I12: =IF(OR(Table24[[#This Row],[Rating]]=4,Table24[[#This Row],[Rating]]=5), 0.05*Table24[[#This Row],[Salary]],0) -> 0 | J12: =VLOOKUP(Table24[[#This Row],[Salary]],'Tax rates'!A$2:C$8, 2) + VLOOKUP(Table24[[#This Row],[Salary]],'Tax rates'!A$2:C$8, 3) * (Table24[[#This Row],[Salary]] - VLOOKUP(Table24[[#This Row],[Salary]],'Tax rates'!A$2:C$8,1)) -> 9154.9 | K12: =Table24[[#This Row],[Salary]]-Table24[[#This Row],[Taxes]] -> 50915.1
A13: Glass, John | B13: Main | C13: Account Management | D13: Contract | E13: 39809 | G13: 58650 | H13: 4 | I13: =IF(OR(Table24[[#This Row],[Rating]]=4,Table24[[#This Row],[Rating]]=5), 0.05*Table24[[#This Row],[Salary]],0) -> 2932.5 | J13: =VLOOKUP(Table24[[#This Row],[Salary]],'Tax rates'!A$2:C$8, 2) + VLOOKUP(Table24[[#This Row],[Salary]],'Tax rates'!A$2:C$8, 3) * (Table24[[#This Row],[Salary]] - VLOOKUP(Table24[[#This Row],[Salary]],'Tax rates'!A$2:C$8,1)) -> 8842.5 | K13: =Table24[[#This Row],[Salary]]-Table24[[#This Row],[Taxes]] -> 49807.5
A14: Soto, Christopher | B14: Main | C14: Account Management | D14: Contract | E14: 36297 | G14: 57990 | H14: 5 | I14: =IF(OR(Table24[[#This Row],[Rating]]=4,Table24[[#This Row],[Rating]]=5), 0.05*Table24[[#This Row],[Salary]],0) -> 2899.5 | J14: =VLOOKUP(Table24[[#This Row],[Salary]],'Tax rates'!A$2:C$8, 2) + VLOOKUP(Table24[[#This Row],[Salary]],'Tax rates'!A$2:C$8, 3) * (Table24[[#This Row],[Salary]] - VLOOKUP(Table24[[#This Row],[Salary]],'Tax rates'!A$2:C$8,1)) -> 8697.3 | K14: =Table24[[#This Row],[Salary]]-Table24[[#This Row],[Taxes]] -> 49292.7
A15: Shaw, Pat | B15: Main | C15: Account Management | D15: Contract | E15: 39592 | G15: 56650 | H15: 1 | I15: =IF(OR(Table24[[#This Row],[Rating]]=4,Table24[[#This Row],[Rating]]=5), 0.05*Table24[[#This Row],[Salary]],0) -> 0 | J15: =VLOOKUP(Table24[[#This Row],[Salary]],'Tax rates'!A$2:C$8, 2) + VLOOKUP(Table24[[#This Row],[Salary]],'Tax rates'!A$2:C$8, 3) * (Table24[[#This Row],[Salary]] - VLOOKUP(Table24[[#This Row],[Salary]],'Tax rates'!A$2:C$8,1)) -> 8402.5 | K15: =Table24[[#This Row],[Salary]]-Table24[[#This Row],[Taxes]] -> 48247.5
A16: Moses, Mark | B16: Main | C16: Account Management | D16: Full Time | E16: 36088 | F16: M | G16: 54580 | H16: 4 | I16: =IF(OR(Table24[[#This Row],[Rating]]=4,Table24[[#This Row],[Rating]]=5), 0.05*Table24[[#This Row],[Salary]],0) -> 2729 | J16: =VLOOKUP(Table24[[#This Row],[Salary]],'Tax rates'!A$2:C$8, 2) + VLOOKUP(Table24[[#This Row],[Salary]],'Tax rates'!A$2:C$8, 3) * (Table24[[#This Row],[Salary]] - VLOOKUP(Table24[[#This Row],[Salary]],'Tax rates'!A$2:C$8,1)) -> 7947.1 | K16: =Table24[[#This Row],[Salary]]-Table24[[#This Row],[Taxes]] -> 46632.9
A17: Frank, William | B17: Main | C17: Account Management | D17: Full Time | E17: 40815 | F17: DM | G17: 54500 | H17: 5 | I17: =IF(OR(Table24[[#This Row],[Rating]]=4,Table24[[#This Row],[Rating]]=5), 0.05*Table24[[#This Row],[Salary]],0) -> 2725 | J17: =VLOOKUP(Table24[[#This Row],[Salary]],'Tax rates'!A$2:C$8, 2) + VLOOKUP(Table24[[#This Row],[Salary]],'Tax rates'!A$2:C$8, 3) * (Table24[[#This Row],[Salary]] - VLOOKUP(Table24[[#This Row],[Salary]],'Tax rates'!A$2:C$8,1)) -> 7929.5 | K17: =Table24[[#This Row],[Salary]]-Table24[[#This Row],[Taxes]] -> 46570.5
A18: Jenkins, Scott | B18: Main | C18: Account Management | D18: Full Time | E18: 40137 | F18: DMR | G18: 54190 | H18: 4 | I18: =IF(OR(Table24[[#This Row],[Rating]]=4,Table24[[#This Row],[Rating]]=5), 0.05*Table24[[#This Row],[Salary]],0) -> 2709.5 | J18: =VLOOKUP(Table24[[#This Row],[Salary]],'Tax rates'!A$2:C$8, 2) + VLOOKUP(Table24[[#This Row],[Salary]],'Tax rates'!A$2:C$8, 3) * (Table24[[#This Row],[Salary]] - VLOOKUP(Table24[[#This Row],[Salary]],'Tax rates'!A$2:C$8,1)) -> 7861.3 | K18: =Table24[[#This Row],[Salary]]-Table24[[#This Row],[Taxes]] -> 46328.7
A19: Mann, Lowell | B19: Main | C19: Account Management | D19: Contract | E19: 40820 | G19: 52750 | H19: 1 | I19: =IF(OR(Table24[[#This Row],[Rating]]=4,Table24[[#This Row],[Rating]]=5), 0.05*Table24[[#This Row],[Salary]],0) -> 0 | J19: =VLOOKUP(Table24[[#This Row],[Salary]],'Tax rates'!A$2:C$8, 2) + VLOOKUP(Table24[[#This Row],[Salary]],'Tax rates'!A$2:C$8, 3) * (Table24[[#This Row],[Salary]] - VLOOKUP(Table24[[#This Row],[Salary]],'Tax rates'!A$2:C$8,1)) -> 7544.5 | K19: =Table24[[#This Row],[Salary]]-Table24[[#This Row],[Taxes]] -> 45205.5
A20: Serrano, Al | B20: Main | C20: Account Management | D20: Full Time | E20: 36673 | F20: D | G20: 48330 | H20: 1 | I20: =IF(OR(Table24[[#This Row],[Rating]]=4,Table24[[#This Row],[Rating]]=5), 0.05*Table24[[#This Row],[Salary]],0) -> 0 | J20: =VLOOKUP(Table24[[#This Row],[Salary]],'Tax rates'!A$2:C$8, 2) + VLOOKUP(Table24[[#This Row],[Salary]],'Tax rates'!A$2:C$8, 3) * (Table24[[#This Row],[Salary]] - VLOOKUP(Table24[[#This Row],[Salary]],'Tax rates'!A$2:C$8,1)) -> 6572.1 | K20: =Table24[[#This Row],[Salary]]-Table24[[#This Row],[Taxes]] -> 41757.9
A21: Ward, Williams | B21: Main | C21: Account Management | D21: Full Time | E21: 39673 | F21: DMR | G21: 48080 | H21: 2 | I21: =IF(OR(Table24[[#This Row],[Rating]]=4,Table24[[#This Row],[Rating]]=5), 0.05*Table24[[#This Row],[Salary]],0) -> 0 | J21: =VLOOKUP(Table24[[#This Row],[Salary]],'Tax rates'!A$2:C$8, 2) + VLOOKUP(Table24[[#This Row],[Salary]],'Tax rates'!A$2:C$8, 3) * (Table24[[#This Row],[Salary]] - VLOOKUP(Table24[[#This Row],[Salary]],'Tax rates'!A$2:C$8,1)) -> 6517.1 | K21: =Table24[[#This Row],[Salary]]-Table24[[#This Row],[Taxes]] -> 41562.9
A22: Bean, Deborah | B22: Main | C22: Account Management | D22: Full Time | E22: 40332 | F22: DMR | G22: 47340 | H22: 2 | I22: =IF(OR(Table24[[#This Row],[Rating]]=4,Table24[[#This Row],[Rating]]=5), 0.05*Table24[[#This Row],[Salary]],0) -> 0 | J22: =VLOOKUP(Table24[[#This Row],[Salary]],'Tax rates'!A$2:C$8, 2) + VLOOKUP(Table24[[#This Row],[Salary]],'Tax rates'!A$2:C$8, 3) * (Table24[[#This Row],[Salary]] - VLOOKUP(Table24[[#This Row],[Salary]],'Tax rates'!A$2:C$8,1)) -> 6354.3 | K22: =Table24[[#This Row],[Salary]]-Table24[[#This Row],[Taxes]] -> 40985.7
A23: Carter, Allan | B23: Main | C23: Account Management | D23: Full Time | E23: 36195 | F23: M | G23: 46360 | H23: 5 | I23: =IF(OR(Table24[[#This Row],[Rating]]=4,Table24[[#This Row],[Rating]]=5), 0.05*Table24[[#This Row],[Salary]],0) -> 2318 | J23: =VLOOKUP(Table24[[#This Row],[Salary]],'Tax rates'!A$2:C$8, 2) + VLOOKUP(Table24[[#This Row],[Salary]],'Tax rates'!A$2:C$8, 3) * (Table24[[#This Row],[Salary]] - VLOOKUP(Table24[[#This Row],[Salary]],'Tax rates'!A$2:C$8,1)) -> 6138.7 | K23: =Table24[[#This Row],[Salary]]-Table24[[#This Row],[Taxes]] -> 40221.3
A24: Solis, Daniel | B24: Main | C24: Account Management | D24: Contract | E24: 41254 | G24: 44720 | H24: 2 | I24: =IF(OR(Table24[[#This Row],[Rating]]=4,Table24[[#This Row],[Rating]]=5), 0.05*Table24[[#This Row],[Salary]],0) -> 0 | J24: =VLOOKUP(Table24[[#This Row],[Salary]],'Tax rates'!A$2:C$8, 2) + VLOOKUP(Table24[[#This Row],[Salary]],'Tax rates'!A$2:C$8, 3) * (Table24[[#This Row],[Salary]] - VLOOKUP(Table24[[#This Row],[Salary]],'Tax rates'!A$2:C$8,1)) -> 5777.9 | K24: =Table24[[#This Row],[Salary]]-Table24[[#This Row],[Taxes]] -> 38942.1
A25: Wiley, Gustavo | B25: Main | C25: Account Management | D25: Contract | E25: 40404 | G25: 39550 | H25: 5 | I25: =IF(OR(Table24[[#This Row],[Rating]]=4,Table24[[#This Row],[Rating]]=5), 0.05*Table24[[#This Row],[Salary]],0) -> 1977.5 | J25: =VLOOKUP(Table24[[#This Row],[Salary]],'Tax rates'!A$2:C$8, 2) + VLOOKUP(Table24[[#This Row],[Salary]],'Tax rates'!A$2:C$8, 3) * (Table24[[#This Row],[Salary]] - VLOOKUP(Table24[[#This Row],[Salary]],'Tax rates'!A$2:C$8,1)) -> 4640.5 | K25: =Table24[[#This Row],[Salary]]-Table24[[#This Row],[Taxes]] -> 34909.5
A26: Preston, Chris | B26: Main | C26: Account Management | D26: Full Time | E26: 35990 | F26: D | G26: 36890 | H26: 1 | I26: =IF(OR(Table24[[#This Row],[Rating]]=4,Table24[[#This Row],[Rating]]=5), 0.05*Table24[[#This Row],[Salary]],0) -> 0 | J26: =VLOOKUP(Table24[[#This Row],[Salary]],'Tax rates'!A$2:C$8, 2) + VLOOKUP(Table24[[#This Row],[Salary]],'Tax rates'!A$2:C$8, 3) * (Table24[[#This Row],[Salary]] - VLOOKUP(Table24[[#This Row],[Salary]],'Tax rates'!A$2:C$8,1)) -> 4236.3 | K26: =Table24[[#This Row],[Salary]]-Table24[[#This Row],[Taxes]] -> 32653.7
A27: Howell, Douglas | B27: Main | C27: Account Management | D27: Hourly | E27: 36380 | G27: 36052 | H27: 5 | I27: =IF(OR(Table24[[#This Row],[Rating]]=4,Table24[[#This Row],[Rating]]=5), 0.05*Table24[[#This Row],[Salary]],0) -> 1802.6 | J27: =VLOOKUP(Table24[[#This Row],[Salary]],'Tax rates'!A$2:C$8, 2) + VLOOKUP(Table24[[#This Row],[Salary]],'Tax rates'!A$2:C$8, 3) * (Table24[[#This Row],[Salary]] - VLOOKUP(Table24[[#This Row],[Salary]],'Tax rates'!A$2:C$8,1)) -> 4135.74 | K27: =Table24[[#This Row],[Salary]]-Table24[[#This Row],[Taxes]] -> 31916.26
A28: Gutierrez, Regina | B28: Main | C28: Account Management | D28: Contract | E28: 39109 | G28: 33120 | H28: 2 | I28: =IF(OR(Table24[[#This Row],[Rating]]=4,Table24[[#This Row],[Rating]]=5), 0.05*Table24[[#This Row],[Salary]],0) -> 0 | J28: =VLOOKUP(Table24[[#This Row],[Salary]],'Tax rates'!A$2:C$8, 2) + VLOOKUP(Table24[[#This Row],[Salary]],'Tax rates'!A$2:C$8, 3) * (Table24[[#This Row],[Salary]] - VLOOKUP(Table24[[#This Row],[Salary]],'Tax rates'!A$2:C$8,1)) -> 3783.9 | K28: =Table24[[#This Row],[Salary]]-Table24[[#This Row],[Taxes]] -> 29336.1
A29: Wilson, Jessica | B29: Main | C29: Account Management | D29: Full Time | E29: 37138 | F29: DMR | G29: 29130 | H29: 1 | I29: =IF(OR(Table24[[#This Row],[Rating]]=4,Table24[[#This Row],[Rating]]=5), 0.05*Table24[[#This Row],[Salary]],0) -> 0 | J29: =VLOOKUP(Table24[[#This Row],[Salary]],'Tax rates'!A$2:C$8, 2) + VLOOKUP(Table24[[#This Row],[Salary]],'Tax rates'!A$2:C$8, 3) * (Table24[[#This Row],[Salary]] - VLOOKUP(Table24[[#This Row],[Salary]],'Tax rates'!A$2:C$8,1)) -> 3305.1 | K29: =Table24[[#This Row],[Salary]]-Table24[[#This Row],[Taxes]] -> 25824.9
A30: Cabe, Max | B30: Main | C30: Account Management | D30: Half-Time | E30: 40166 | F30: D | G30: 25245 | H30: 5 | I30: =IF(OR(Table24[[#This Row],[Rating]]=4,Table24[[#This Row],[Rating]]=5), 0.05*Table24[[#This Row],[Salary]],0) -> 1262.25 | J30: =VLOOKUP(Table24[[#This Row],[Salary]],'Tax rates'!A$2:C$8, 2) + VLOOKUP(Table24[[#This Row],[Salary]],'Tax rates'!A$2:C$8, 3) * (Table24[[#This Row],[Salary]] - VLOOKUP(Table24[[#This Row],[Salary]],'Tax rates'!A$2:C$8,1)) -> 2838.9 | K30: =Table24[[#This Row],[Salary]]-Table24[[#This Row],[Taxes]] -> 22406.1
A31: Lynch, Scott | B31: Main | C31: Account Management | D31: Full Time | E31: 40666 | F31: DMR | G31: 24090 | H31: 4 | I31: =IF(OR(Table24[[#This Row],[Rating]]=4,Table24[[#This Row],[Rating]]=5), 0.05*Table24[[#This Row],[Salary]],0) -> 1204.5 | J31: =VLOOKUP(Table24[[#This Row],[Salary]],'Tax rates'!A$2:C$8, 2) + VLOOKUP(Table24[[#This Row],[Salary]],'Tax rates'!A$2:C$8, 3) * (Table24[[#This Row],[Salary]] - VLOOKUP(Table24[[#This Row],[Salary]],'Tax rates'!A$2:C$8,1)) -> 2700.3 | K31: =Table24[[#This Row],[Salary]]-Table24[[#This Row],[Taxes]] -> 21389.7
A32: Ayala, Polly | B32: Main | C32: Account Management | D32: Full Time | E32: 39174 | F32: DMR | G32: 23320 | H32: 4 | I32: =IF(OR(Table24[[#This Row],[Rating]]=4,Table24[[#This Row],[Rating]]=5), 0.05*Table24[[#This Row],[Salary]],0) -> 1166 | J32: =VLOOKUP(Table24[[#This Row],[Salary]],'Tax rates'!A$2:C$8, 2) + VLOOKUP(Table24[[#This Row],[Salary]],'Tax rates'!A$2:C$8, 3) * (Table24[[#This Row],[Salary]] - VLOOKUP(Table24[[#This Row],[Salary]],'Tax rates'!A$2:C$8,1)) -> 2607.9 | K32: =Table24[[#This Row],[Salary]]-Table24[[#This Row],[Taxes]] -> 20712.1
A33: Curry, Hunyen | B33: Main | C33: Account Management | D33: Half-Time | E33: 37249 | F33: D | G33: 12545 | H33: 4 | I33: =IF(OR(Table24[[#This Row],[Rating]]=4,Table24[[#This Row],[Rating]]=5), 0.05*Table24[[#This Row],[Salary]],0) -> 627.25 | J33: =VLOOKUP(Table24[[#This Row],[Salary]],'Tax rates'!A$2:C$8, 2) + VLOOKUP(Table24[[#This Row],[Salary]],'Tax rates'!A$2:C$8, 3) * (Table24[[#This Row],[Salary]] - VLOOKUP(Table24[[#This Row],[Salary]],'Tax rates'!A$2:C$8,1)) -> 1314.9 | K33: =Table24[[#This Row],[Salary]]-Table24[[#This Row],[Taxes]] -> 11230.1
A34: Allison, Timothy | B34: Main | C34: Creative | D34: Full Time | E34: 40918 | F34: M | G34: 82500 | H34: 5 | I34: =IF(OR(Table24[[#This Row],[Rating]]=4,Table24[[#This Row],[Rating]]=5), 0.05*Table24[[#This Row],[Salary]],0) -> 4125 | J34: =VLOOKUP(Table24[[#This Row],[Salary]],'Tax rates'!A$2:C$8, 2) + VLOOKUP(Table24[[#This Row],[Salary]],'Tax rates'!A$2:C$8, 3) * (Table24[[#This Row],[Salary]] - VLOOKUP(Table24[[#This Row],[Salary]],'Tax rates'!A$2:C$8,1)) -> 14089.5 | K34: =Table24[[#This Row],[Salary]]-Table24[[#This Row],[Taxes]] -> 68410.5
A35: Figueroa, Leonard | B35: Main | C35: Creative | D35: Contract | E35: 39024 | G35: 76020 | H35: 1 | I35: =IF(OR(Table24[[#This Row],[Rating]]=4,Table24[[#This Row],[Rating]]=5), 0.05*Table24[[#This Row],[Salary]],0) -> 0 | J35: =VLOOKUP(Table24[[#This Row],[Salary]],'Tax rates'!A$2:C$8, 2) + VLOOKUP(Table24[[#This Row],[Salary]],'Tax rates'!A$2:C$8, 3) * (Table24[[#This Row],[Salary]] - VLOOKUP(Table24[[#This Row],[Salary]],'Tax rates'!A$2:C$8,1)) -> 12663.9 | K35: =Table24[[#This Row],[Salary]]-Table24[[#This Row],[Taxes]] -> 63356.1
A36: Roberson, Eileen | B36: Main | C36: Creative | D36: Contract | E36: 35959 | G36: 64470 | H36: 3 | I36: =IF(OR(Table24[[#This Row],[Rating]]=4,Table24[[#This Row],[Rating]]=5), 0.05*Table24[[#This Row],[Salary]],0) -> 0 | J36: =VLOOKUP(Table24[[#This Row],[Salary]],'Tax rates'!A$2:C$8, 2) + VLOOKUP(Table24[[#This Row],[Salary]],'Tax rates'!A$2:C$8, 3) * (Table24[[#This Row],[Salary]] - VLOOKUP(Table24[[#This Row],[Salary]],'Tax rates'!A$2:C$8,1)) -> 10122.9 | K36: =Table24[[#This Row],[Salary]]-Table24[[#This Row],[Taxes]] -> 54347.1
A37: Molina, Michael | B37: Main | C37: Creative | D37: Full Time | E37: 37113 | F37: M | G37: 61150 | H37: 4 | I37: =IF(OR(Table24[[#This Row],[Rating]]=4,Table24[[#This Row],[Rating]]=5), 0.05*Table24[[#This Row],[Salary]],0) -> 3057.5 | J37: =VLOOKUP(Table24[[#This Row],[Salary]],'Tax rates'!A$2:C$8, 2) + VLOOKUP(Table24[[#This Row],[Salary]],'Tax rates'!A$2:C$8, 3) * (Table24[[#This Row],[Salary]] - VLOOKUP(Table24[[#This Row],[Salary]],'Tax rates'!A$2:C$8,1)) -> 9392.5 | K37: =Table24[[#This Row],[Salary]]-Table24[[#This Row],[Taxes]] -> 51757.5
A38: McDowell, Scott | B38: Main | C38: Creative | D38: Full Time | E38: 36077 | F38: R | G38: 50110 | H38: 1 | I38: =IF(OR(Table24[[#This Row],[Rating]]=4,Table24[[#This Row],[Rating]]=5), 0.05*Table24[[#This Row],[Salary]],0) -> 0 | J38: =VLOOKUP(Table24[[#This Row],[Salary]],'Tax rates'!A$2:C$8, 2) + VLOOKUP(Table24[[#This Row],[Salary]],'Tax rates'!A$2:C$8, 3) * (Table24[[#This Row],[Salary]] - VLOOKUP(Table24[[#This Row],[Salary]],'Tax rates'!A$2:C$8,1)) -> 6963.7 | K38: =Table24[[#This Row],[Salary]]-Table24[[#This Row],[Taxes]] -> 43146.3
A39: Silva, Stephen | B39: Main | C39: Creative | D39: Half-Time | E39: 36357 | F39: D | G39: 42905 | H39: 1 | I39: =IF(OR(Table24[[#This Row],[Rating]]=4,Table24[[#This Row],[Rating]]=5), 0.05*Table24[[#This Row],[Salary]],0) -> 0 | J39: =VLOOKUP(Table24[[#This Row],[Salary]],'Tax rates'!A$2:C$8, 2) + VLOOKUP(Table24[[#This Row],[Salary]],'Tax rates'!A$2:C$8, 3) * (Table24[[#This Row],[Salary]] - VLOOKUP(Table24[[#This Row],[Salary]],'Tax rates'!A$2:C$8,1)) -> 5378.6 | K39: =Table24[[#This Row],[Salary]]-Table24[[#This Row],[Taxes]] -> 37526.4
A40: McKenzie, Michelle | B40: Main | C40: Environmental Compliance | D40: Full Time | E40: 38746 | F40: R | G40: 49360 | H40: 2 | I40: =IF(OR(Table24[[#This Row],[Rating]]=4,Table24[[#This Row],[Rating]]=5), 0.05*Table24[[#This Row],[Salary]],0) -> 0 | J40: =VLOOKUP(Table24[[#This Row],[Salary]],'Tax rates'!A$2:C$8, 2) + VLOOKUP(Table24[[#This Row],[Salary]],'Tax rates'!A$2:C$8, 3) * (Table24[[#This Row],[Salary]] - VLOOKUP(Table24[[#This Row],[Salary]],'Tax rates'!A$2:C$8,1)) -> 6798.7 | K40: =Table24[[#This Row],[Salary]]-Table24[[#This Row],[Taxes]] -> 42561.3
...

Sheet Data validation lists
A1: Buildings | C1: Departments | E1: Job status | G1: Ratings
A2: Main | C2: Account Management | E2: Contract | G2: 1
A3: North | C3: ADC | E3: Full Time | G3: 2
A4: South | C4: Creative | E4: Half-Time | G4: 3
A5: Taft | C5: Environmental Compliance | E5: Hourly | G5: 4
A6: Watson | C6: Environmental Health/Safety | G6: 5
A7: West | C7: Facilities/Engineering
C8: Green Building
C9: Human Resources
C10: IT
C11: Major Mfg Projects
C12: Manufacturing
C13: Manufacturing Admin
C14: Marketing
C15: Product Development
C16: Professional Training Group
C17: Quality Assurance
C18: Quality Control
C19: Research Center
... C22: Training
